[2025-03-05 09:25:06 +0100] [339016] [INFO] Starting gunicorn 23.0.0
[2025-03-05 09:25:06 +0100] [339016] [INFO] Listening at: http://127.0.0.1:5000 (339016)
[2025-03-05 09:25:06 +0100] [339016] [INFO] Using worker: sync
[2025-03-05 09:25:06 +0100] [339017] [INFO] Booting worker with pid: 339017
[2025-03-05 09:25:06 +0100] [339018] [INFO] Booting worker with pid: 339018
[2025-03-05 09:25:06 +0100] [339019] [INFO] Booting worker with pid: 339019
[2025-03-05 09:25:06 +0100] [339020] [INFO] Booting worker with pid: 339020
[2025-03-05 09:25:53 +0100] [339016] [CRITICAL] WORKER TIMEOUT (pid:339018)
[2025-03-05 09:25:53 +0100] [339018] [ERROR] Error handling request (no URI read)
Traceback (most recent call last):
  File "/home/meriam/meriam-hfaidhia-4DS4-mlops_project/venv/lib/python3.12/site-packages/gunicorn/workers/sync.py", line 133, in handle
    req = next(parser)
          ^^^^^^^^^^^^
  File "/home/meriam/meriam-hfaidhia-4DS4-mlops_project/venv/lib/python3.12/site-packages/gunicorn/http/parser.py", line 41, in __next__
    self.mesg = self.mesg_class(self.cfg, self.unreader, self.source_addr, self.req_count)
                ^^^^^^^^^^^^^^^^^^^^^^^^^^^^^^^^^^^^^^^^^^^^^^^^^^^^^^^^^^^^^^^^^^^^^^^^^^
  File "/home/meriam/meriam-hfaidhia-4DS4-mlops_project/venv/lib/python3.12/site-packages/gunicorn/http/message.py", line 259, in __init__
    super().__init__(cfg, unreader, peer_addr)
  File "/home/meriam/meriam-hfaidhia-4DS4-mlops_project/venv/lib/python3.12/site-packages/gunicorn/http/message.py", line 60, in __init__
    unused = self.parse(self.unreader)
             ^^^^^^^^^^^^^^^^^^^^^^^^^
  File "/home/meriam/meriam-hfaidhia-4DS4-mlops_project/venv/lib/python3.12/site-packages/gunicorn/http/message.py", line 271, in parse
    self.get_data(unreader, buf, stop=True)
  File "/home/meriam/meriam-hfaidhia-4DS4-mlops_project/venv/lib/python3.12/site-packages/gunicorn/http/message.py", line 262, in get_data
    data = unreader.read()
           ^^^^^^^^^^^^^^^
  File "/home/meriam/meriam-hfaidhia-4DS4-mlops_project/venv/lib/python3.12/site-packages/gunicorn/http/unreader.py", line 36, in read
    d = self.chunk()
        ^^^^^^^^^^^^
  File "/home/meriam/meriam-hfaidhia-4DS4-mlops_project/venv/lib/python3.12/site-packages/gunicorn/http/unreader.py", line 63, in chunk
    return self.sock.recv(self.mxchunk)
           ^^^^^^^^^^^^^^^^^^^^^^^^^^^^
  File "/home/meriam/meriam-hfaidhia-4DS4-mlops_project/venv/lib/python3.12/site-packages/gunicorn/workers/base.py", line 204, in handle_abort
    sys.exit(1)
SystemExit: 1
[2025-03-05 09:25:53 +0100] [339018] [INFO] Worker exiting (pid: 339018)
[2025-03-05 09:25:54 +0100] [339710] [INFO] Booting worker with pid: 339710
[2025-03-05 09:26:54 +0100] [339016] [CRITICAL] WORKER TIMEOUT (pid:339020)
[2025-03-05 09:26:54 +0100] [339020] [ERROR] Error handling request (no URI read)
Traceback (most recent call last):
  File "/home/meriam/meriam-hfaidhia-4DS4-mlops_project/venv/lib/python3.12/site-packages/gunicorn/workers/sync.py", line 133, in handle
    req = next(parser)
          ^^^^^^^^^^^^
  File "/home/meriam/meriam-hfaidhia-4DS4-mlops_project/venv/lib/python3.12/site-packages/gunicorn/http/parser.py", line 41, in __next__
    self.mesg = self.mesg_class(self.cfg, self.unreader, self.source_addr, self.req_count)
                ^^^^^^^^^^^^^^^^^^^^^^^^^^^^^^^^^^^^^^^^^^^^^^^^^^^^^^^^^^^^^^^^^^^^^^^^^^
  File "/home/meriam/meriam-hfaidhia-4DS4-mlops_project/venv/lib/python3.12/site-packages/gunicorn/http/message.py", line 259, in __init__
    super().__init__(cfg, unreader, peer_addr)
  File "/home/meriam/meriam-hfaidhia-4DS4-mlops_project/venv/lib/python3.12/site-packages/gunicorn/http/message.py", line 60, in __init__
    unused = self.parse(self.unreader)
             ^^^^^^^^^^^^^^^^^^^^^^^^^
  File "/home/meriam/meriam-hfaidhia-4DS4-mlops_project/venv/lib/python3.12/site-packages/gunicorn/http/message.py", line 271, in parse
    self.get_data(unreader, buf, stop=True)
  File "/home/meriam/meriam-hfaidhia-4DS4-mlops_project/venv/lib/python3.12/site-packages/gunicorn/http/message.py", line 262, in get_data
    data = unreader.read()
           ^^^^^^^^^^^^^^^
  File "/home/meriam/meriam-hfaidhia-4DS4-mlops_project/venv/lib/python3.12/site-packages/gunicorn/http/unreader.py", line 36, in read
    d = self.chunk()
        ^^^^^^^^^^^^
  File "/home/meriam/meriam-hfaidhia-4DS4-mlops_project/venv/lib/python3.12/site-packages/gunicorn/http/unreader.py", line 63, in chunk
    return self.sock.recv(self.mxchunk)
           ^^^^^^^^^^^^^^^^^^^^^^^^^^^^
  File "/home/meriam/meriam-hfaidhia-4DS4-mlops_project/venv/lib/python3.12/site-packages/gunicorn/workers/base.py", line 204, in handle_abort
    sys.exit(1)
SystemExit: 1
[2025-03-05 09:26:54 +0100] [339020] [INFO] Worker exiting (pid: 339020)
[2025-03-05 09:26:54 +0100] [339830] [INFO] Booting worker with pid: 339830
2025/03/05 09:27:22 ERROR mlflow.server: Exception on /ajax-api/2.0/mlflow/runs/search [POST]
Traceback (most recent call last):
  File "/home/meriam/meriam-hfaidhia-4DS4-mlops_project/venv/lib/python3.12/site-packages/flask/app.py", line 1511, in wsgi_app
  File "/home/meriam/meriam-hfaidhia-4DS4-mlops_project/venv/lib/python3.12/site-packages/flask/app.py", line 919, in full_dispatch_request
  File "/home/meriam/meriam-hfaidhia-4DS4-mlops_project/venv/lib/python3.12/site-packages/flask/app.py", line 917, in full_dispatch_request
  File "/home/meriam/meriam-hfaidhia-4DS4-mlops_project/venv/lib/python3.12/site-packages/flask/app.py", line 902, in dispatch_request
  File "/home/meriam/meriam-hfaidhia-4DS4-mlops_project/venv/lib/python3.12/site-packages/mlflow/server/handlers.py", line 573, in wrapper
  File "/home/meriam/meriam-hfaidhia-4DS4-mlops_project/venv/lib/python3.12/site-packages/mlflow/server/handlers.py", line 614, in wrapper
  File "/home/meriam/meriam-hfaidhia-4DS4-mlops_project/venv/lib/python3.12/site-packages/mlflow/server/handlers.py", line 1004, in _search_runs
  File "/home/meriam/meriam-hfaidhia-4DS4-mlops_project/venv/lib/python3.12/site-packages/mlflow/server/handlers.py", line 1020, in search_runs_impl
  File "/home/meriam/meriam-hfaidhia-4DS4-mlops_project/venv/lib/python3.12/site-packages/mlflow/server/handlers.py", line 346, in _get_tracking_store
  File "/home/meriam/meriam-hfaidhia-4DS4-mlops_project/venv/lib/python3.12/site-packages/mlflow/tracking/_tracking_service/registry.py", line 45, in get_store
  File "/home/meriam/meriam-hfaidhia-4DS4-mlops_project/venv/lib/python3.12/site-packages/mlflow/tracking/_tracking_service/registry.py", line 56, in _get_store_with_resolved_uri
  File "/home/meriam/meriam-hfaidhia-4DS4-mlops_project/venv/lib/python3.12/site-packages/mlflow/server/handlers.py", line 165, in _get_sqlalchemy_store
ModuleNotFoundError: No module named 'mlflow.store.tracking.sqlalchemy_store'
[2025-03-05 09:27:26 +0100] [339017] [INFO] Worker exiting (pid: 339017)
[2025-03-05 09:27:27 +0100] [340034] [INFO] Booting worker with pid: 340034
[2025-03-05 09:27:27 +0100] [340034] [ERROR] Exception in worker process
Traceback (most recent call last):
  File "/home/meriam/meriam-hfaidhia-4DS4-mlops_project/venv/lib/python3.12/site-packages/gunicorn/arbiter.py", line 608, in spawn_worker
  File "/home/meriam/meriam-hfaidhia-4DS4-mlops_project/venv/lib/python3.12/site-packages/gunicorn/workers/base.py", line 135, in init_process
  File "/home/meriam/meriam-hfaidhia-4DS4-mlops_project/venv/lib/python3.12/site-packages/gunicorn/workers/base.py", line 147, in load_wsgi
  File "/home/meriam/meriam-hfaidhia-4DS4-mlops_project/venv/lib/python3.12/site-packages/gunicorn/app/base.py", line 66, in wsgi
  File "/home/meriam/meriam-hfaidhia-4DS4-mlops_project/venv/lib/python3.12/site-packages/gunicorn/app/wsgiapp.py", line 57, in load
  File "/home/meriam/meriam-hfaidhia-4DS4-mlops_project/venv/lib/python3.12/site-packages/gunicorn/app/wsgiapp.py", line 47, in load_wsgiapp
  File "/home/meriam/meriam-hfaidhia-4DS4-mlops_project/venv/lib/python3.12/site-packages/gunicorn/util.py", line 370, in import_app
  File "/usr/lib/python3.12/importlib/__init__.py", line 90, in import_module
    return _bootstrap._gcd_import(name[level:], package, level)
           ^^^^^^^^^^^^^^^^^^^^^^^^^^^^^^^^^^^^^^^^^^^^^^^^^^^^
  File "<frozen importlib._bootstrap>", line 1387, in _gcd_import
  File "<frozen importlib._bootstrap>", line 1360, in _find_and_load
  File "<frozen importlib._bootstrap>", line 1310, in _find_and_load_unlocked
  File "<frozen importlib._bootstrap>", line 488, in _call_with_frames_removed
  File "<frozen importlib._bootstrap>", line 1387, in _gcd_import
  File "<frozen importlib._bootstrap>", line 1360, in _find_and_load
  File "<frozen importlib._bootstrap>", line 1324, in _find_and_load_unlocked
ModuleNotFoundError: No module named 'mlflow'
[2025-03-05 09:27:27 +0100] [340034] [INFO] Worker exiting (pid: 340034)
[2025-03-05 09:27:27 +0100] [339016] [ERROR] Worker (pid:340034) exited with code 3
[2025-03-05 09:27:27 +0100] [339710] [INFO] Worker exiting (pid: 339710)
[2025-03-05 09:27:27 +0100] [339019] [INFO] Worker exiting (pid: 339019)
[2025-03-05 09:27:27 +0100] [339016] [ERROR] Worker (pid:339019) was sent SIGTERM!
[2025-03-05 09:27:57 +0100] [339016] [ERROR] Shutting down: Master
[2025-03-05 09:27:57 +0100] [339016] [ERROR] Reason: Worker failed to boot.
